{"message": "Internal Server Error: /accounts/google/login/\nTraceback (most recent call last):\n  File \"/opt/pysetup/.venv/lib/python3.9/site-packages/django_redis/cache.py\", line 29, in _decorator\n    return method(self, *args, **kwargs)\n  File \"/opt/pysetup/.venv/lib/python3.9/site-packages/django_redis/cache.py\", line 138, in has_key\n    return self.client.has_key(*args, **kwargs)\n  File \"/opt/pysetup/.venv/lib/python3.9/site-packages/django_redis/client/default.py\", line 670, in has_key\n    raise ConnectionInterrupted(connection=client) from e\ndjango_redis.exceptions.ConnectionInterrupted: Redis MasterNotFoundError: No master found for 'mymaster' : Redis<ConnectionPool<Connection<host=redis-sentinel-headless,port=26379,db=0>>> - ConnectionError('Connection closed by server.')\n\nDuring handling of the above exception, another exception occurred:\n\nTraceback (most recent call last):\n  File \"/opt/pysetup/.venv/lib/python3.9/site-packages/django/core/handlers/exception.py\", line 47, in inner\n    response = get_response(request)\n  File \"/opt/pysetup/.venv/lib/python3.9/site-packages/django/utils/deprecation.py\", line 119, in __call__\n    response = self.process_response(request, response)\n  File \"/opt/pysetup/.venv/lib/python3.9/site-packages/django/contrib/sessions/middleware.py\", line 61, in process_response\n    request.session.save()\n  File \"/opt/pysetup/.venv/lib/python3.9/site-packages/django/contrib/sessions/backends/cache.py\", line 56, in save\n    return self.create()\n  File \"/opt/pysetup/.venv/lib/python3.9/site-packages/django/contrib/sessions/backends/cache.py\", line 43, in create\n    self._session_key = self._get_new_session_key()\n  File \"/opt/pysetup/.venv/lib/python3.9/site-packages/django/contrib/sessions/backends/base.py\", line 196, in _get_new_session_key\n    if not self.exists(session_key):\n  File \"/opt/pysetup/.venv/lib/python3.9/site-packages/django/contrib/sessions/backends/cache.py\", line 70, in exists\n    return bool(session_key) and (self.cache_key_prefix + session_key) in self._cache\n  File \"/opt/pysetup/.venv/lib/python3.9/site-packages/django/core/cache/backends/base.py\", line 212, in __contains__\n    return self.has_key(key)\n  File \"/opt/pysetup/.venv/lib/python3.9/site-packages/django_redis/cache.py\", line 36, in _decorator\n    raise e.__cause__\n  File \"/opt/pysetup/.venv/lib/python3.9/site-packages/django_redis/client/default.py\", line 668, in has_key\n    return client.exists(key) == 1\n  File \"/opt/pysetup/.venv/lib/python3.9/site-packages/redis/commands/core.py\", line 1736, in exists\n    return self.execute_command(\"EXISTS\", *names)\n  File \"/opt/pysetup/.venv/lib/python3.9/site-packages/redis/client.py\", line 533, in execute_command\n    conn = self.connection or pool.get_connection(command_name, **options)\n  File \"/opt/pysetup/.venv/lib/python3.9/site-packages/redis/connection.py\", line 1096, in get_connection\n    connection.connect()\n  File \"/opt/pysetup/.venv/lib/python3.9/site-packages/redis/sentinel.py\", line 55, in connect\n    return self.retry.call_with_retry(self._connect_retry, lambda error: None)\n  File \"/opt/pysetup/.venv/lib/python3.9/site-packages/redis/retry.py\", line 51, in call_with_retry\n    raise error\n  File \"/opt/pysetup/.venv/lib/python3.9/site-packages/redis/retry.py\", line 46, in call_with_retry\n    return do()\n  File \"/opt/pysetup/.venv/lib/python3.9/site-packages/redis/sentinel.py\", line 45, in _connect_retry\n    self.connect_to(self.connection_pool.get_master_address())\n  File \"/opt/pysetup/.venv/lib/python3.9/site-packages/redis/sentinel.py\", line 107, in get_master_address\n    master_address = self.sentinel_manager.discover_master(self.service_name)\n  File \"/opt/pysetup/.venv/lib/python3.9/site-packages/redis/sentinel.py\", line 301, in discover_master\n    raise MasterNotFoundError(f\"No master found for {service_name!r}{error_info}\")\nredis.sentinel.MasterNotFoundError: No master found for 'mymaster' : Redis<ConnectionPool<Connection<host=redis-sentinel-headless,port=26379,db=0>>> - ConnectionError('Connection closed by server.')","severity": "ERROR", "logging.googleapis.com/labels": {"python_logger": "django.request"}, "logging.googleapis.com/trace": "", "logging.googleapis.com/spanId": "", "logging.googleapis.com/trace_sampled": false, "logging.googleapis.com/sourceLocation": {"line": 224, "file": "/opt/pysetup/.venv/lib/python3.9/site-packages/django/utils/log.py", "function": "log_response"}, "httpRequest": {} }
{"message": "500 POST /api/v3/token/ (10.68.13.6) 82.70ms","severity": "ERROR", "logging.googleapis.com/labels": {"python_logger": "hurricane.server.access"}, "logging.googleapis.com/trace": "", "logging.googleapis.com/spanId": "", "logging.googleapis.com/trace_sampled": false, "logging.googleapis.com/sourceLocation": {"line": 80, "file": "/opt/pysetup/.venv/lib/python3.9/site-packages/hurricane/server/__init__.py", "function": "log_request"}, "httpRequest": {} }
{"message": "Internal Server Error: /accounts/google/login/\nTraceback (most recent call last):\n  File \"/opt/pysetup/.venv/lib/python3.9/site-packages/django_redis/cache.py\", line 29, in _decorator\n    return method(self, *args, **kwargs)\n  File \"/opt/pysetup/.venv/lib/python3.9/site-packages/django_redis/cache.py\", line 138, in has_key\n    return self.client.has_key(*args, **kwargs)\n  File \"/opt/pysetup/.venv/lib/python3.9/site-packages/django_redis/client/default.py\", line 670, in has_key\n    raise ConnectionInterrupted(connection=client) from e\ndjango_redis.exceptions.ConnectionInterrupted: Redis MasterNotFoundError: No master found for 'mymaster' : Redis<ConnectionPool<Connection<host=redis-sentinel-headless,port=26379,db=0>>> - ConnectionError('Connection closed by server.')\n\nDuring handling of the above exception, another exception occurred:\n\nTraceback (most recent call last):\n  File \"/opt/pysetup/.venv/lib/python3.9/site-packages/django/core/handlers/exception.py\", line 47, in inner\n    response = get_response(request)\n  File \"/opt/pysetup/.venv/lib/python3.9/site-packages/django/utils/deprecation.py\", line 119, in __call__\n    response = self.process_response(request, response)\n  File \"/opt/pysetup/.venv/lib/python3.9/site-packages/django/contrib/sessions/middleware.py\", line 61, in process_response\n    request.session.save()\n  File \"/opt/pysetup/.venv/lib/python3.9/site-packages/django/contrib/sessions/backends/cache.py\", line 56, in save\n    return self.create()\n  File \"/opt/pysetup/.venv/lib/python3.9/site-packages/django/contrib/sessions/backends/cache.py\", line 43, in create\n    self._session_key = self._get_new_session_key()\n  File \"/opt/pysetup/.venv/lib/python3.9/site-packages/django/contrib/sessions/backends/base.py\", line 196, in _get_new_session_key\n    if not self.exists(session_key):\n  File \"/opt/pysetup/.venv/lib/python3.9/site-packages/django/contrib/sessions/backends/cache.py\", line 70, in exists\n    return bool(session_key) and (self.cache_key_prefix + session_key) in self._cache\n  File \"/opt/pysetup/.venv/lib/python3.9/site-packages/django/core/cache/backends/base.py\", line 212, in __contains__\n    return self.has_key(key)\n  File \"/opt/pysetup/.venv/lib/python3.9/site-packages/django_redis/cache.py\", line 36, in _decorator\n    raise e.__cause__\n  File \"/opt/pysetup/.venv/lib/python3.9/site-packages/django_redis/client/default.py\", line 668, in has_key\n    return client.exists(key) == 1\n  File \"/opt/pysetup/.venv/lib/python3.9/site-packages/redis/commands/core.py\", line 1736, in exists\n    return self.execute_command(\"EXISTS\", *names)\n  File \"/opt/pysetup/.venv/lib/python3.9/site-packages/redis/client.py\", line 533, in execute_command\n    conn = self.connection or pool.get_connection(command_name, **options)\n  File \"/opt/pysetup/.venv/lib/python3.9/site-packages/redis/connection.py\", line 1096, in get_connection\n    connection.connect()\n  File \"/opt/pysetup/.venv/lib/python3.9/site-packages/redis/sentinel.py\", line 55, in connect\n    return self.retry.call_with_retry(self._connect_retry, lambda error: None)\n  File \"/opt/pysetup/.venv/lib/python3.9/site-packages/redis/retry.py\", line 51, in call_with_retry\n    raise error\n  File \"/opt/pysetup/.venv/lib/python3.9/site-packages/redis/retry.py\", line 46, in call_with_retry\n    return do()\n  File \"/opt/pysetup/.venv/lib/python3.9/site-packages/redis/sentinel.py\", line 45, in _connect_retry\n    self.connect_to(self.connection_pool.get_master_address())\n  File \"/opt/pysetup/.venv/lib/python3.9/site-packages/redis/sentinel.py\", line 107, in get_master_address\n    master_address = self.sentinel_manager.discover_master(self.service_name)\n  File \"/opt/pysetup/.venv/lib/python3.9/site-packages/redis/sentinel.py\", line 301, in discover_master\n    raise MasterNotFoundError(f\"No master found for {service_name!r}{error_info}\")\nredis.sentinel.MasterNotFoundError: No master found for 'mymaster' : Redis<ConnectionPool<Connection<host=redis-sentinel-headless,port=26379,db=0>>> - ConnectionError('Connection closed by server.')","severity": "ERROR", "logging.googleapis.com/labels": {"python_logger": "django.request"}, "logging.googleapis.com/trace": "", "logging.googleapis.com/spanId": "", "logging.googleapis.com/trace_sampled": false, "logging.googleapis.com/sourceLocation": {"line": 224, "file": "/opt/pysetup/.venv/lib/python3.9/site-packages/django/utils/log.py", "function": "log_response"}, "httpRequest": {} }
{"message": "500 GET /accounts/google/login/ (10.68.13.6) 50.69ms","severity": "ERROR", "logging.googleapis.com/labels": {"python_logger": "hurricane.server.access"}, "logging.googleapis.com/trace": "", "logging.googleapis.com/spanId": "", "logging.googleapis.com/trace_sampled": false, "logging.googleapis.com/sourceLocation": {"line": 80, "file": "/opt/pysetup/.venv/lib/python3.9/site-packages/hurricane/server/__init__.py", "function": "log_request"}, "httpRequest": {} }
{"message": "Internal Server Error: /accounts/google/login/\nTraceback (most recent call last):\n  File \"/opt/pysetup/.venv/lib/python3.9/site-packages/django_redis/cache.py\", line 29, in _decorator\n    return method(self, *args, **kwargs)\n  File \"/opt/pysetup/.venv/lib/python3.9/site-packages/django_redis/cache.py\", line 138, in has_key\n    return self.client.has_key(*args, **kwargs)\n  File \"/opt/pysetup/.venv/lib/python3.9/site-packages/django_redis/client/default.py\", line 670, in has_key\n    raise ConnectionInterrupted(connection=client) from e\ndjango_redis.exceptions.ConnectionInterrupted: Redis MasterNotFoundError: No master found for 'mymaster' : Redis<ConnectionPool<Connection<host=redis-sentinel-headless,port=26379,db=0>>> - ConnectionError('Connection closed by server.')\n\nDuring handling of the above exception, another exception occurred:\n\nTraceback (most recent call last):\n  File \"/opt/pysetup/.venv/lib/python3.9/site-packages/django/core/handlers/exception.py\", line 47, in inner\n    response = get_response(request)\n  File \"/opt/pysetup/.venv/lib/python3.9/site-packages/django/utils/deprecation.py\", line 119, in __call__\n    response = self.process_response(request, response)\n  File \"/opt/pysetup/.venv/lib/python3.9/site-packages/django/contrib/sessions/middleware.py\", line 61, in process_response\n    request.session.save()\n  File \"/opt/pysetup/.venv/lib/python3.9/site-packages/django/contrib/sessions/backends/cache.py\", line 56, in save\n    return self.create()\n  File \"/opt/pysetup/.venv/lib/python3.9/site-packages/django/contrib/sessions/backends/cache.py\", line 43, in create\n    self._session_key = self._get_new_session_key()\n  File \"/opt/pysetup/.venv/lib/python3.9/site-packages/django/contrib/sessions/backends/base.py\", line 196, in _get_new_session_key\n    if not self.exists(session_key):\n  File \"/opt/pysetup/.venv/lib/python3.9/site-packages/django/contrib/sessions/backends/cache.py\", line 70, in exists\n    return bool(session_key) and (self.cache_key_prefix + session_key) in self._cache\n  File \"/opt/pysetup/.venv/lib/python3.9/site-packages/django/core/cache/backends/base.py\", line 212, in __contains__\n    return self.has_key(key)\n  File \"/opt/pysetup/.venv/lib/python3.9/site-packages/django_redis/cache.py\", line 36, in _decorator\n    raise e.__cause__\n  File \"/opt/pysetup/.venv/lib/python3.9/site-packages/django_redis/client/default.py\", line 668, in has_key\n    return client.exists(key) == 1\n  File \"/opt/pysetup/.venv/lib/python3.9/site-packages/redis/commands/core.py\", line 1736, in exists\n    return self.execute_command(\"EXISTS\", *names)\n  File \"/opt/pysetup/.venv/lib/python3.9/site-packages/redis/client.py\", line 533, in execute_command\n    conn = self.connection or pool.get_connection(command_name, **options)\n  File \"/opt/pysetup/.venv/lib/python3.9/site-packages/redis/connection.py\", line 1086, in get_connection\n    connection.connect()\n  File \"/opt/pysetup/.venv/lib/python3.9/site-packages/redis/sentinel.py\", line 55, in connect\n    return self.retry.call_with_retry(self._connect_retry, lambda error: None)\n  File \"/opt/pysetup/.venv/lib/python3.9/site-packages/redis/retry.py\", line 51, in call_with_retry\n    raise error\n  File \"/opt/pysetup/.venv/lib/python3.9/site-packages/redis/retry.py\", line 46, in call_with_retry\n    return do()\n  File \"/opt/pysetup/.venv/lib/python3.9/site-packages/redis/sentinel.py\", line 45, in _connect_retry\n    self.connect_to(self.connection_pool.get_master_address())\n  File \"/opt/pysetup/.venv/lib/python3.9/site-packages/redis/sentinel.py\", line 107, in get_master_address\n    master_address = self.sentinel_manager.discover_master(self.service_name)\n  File \"/opt/pysetup/.venv/lib/python3.9/site-packages/redis/sentinel.py\", line 301, in discover_master\n    raise MasterNotFoundError(f\"No master found for {service_name!r}{error_info}\")\nredis.sentinel.MasterNotFoundError: No master found for 'mymaster' : Redis<ConnectionPool<Connection<host=redis-sentinel-headless,port=26379,db=0>>> - ConnectionError('Connection closed by server.')","severity": "ERROR", "logging.googleapis.com/labels": {"python_logger": "django.request"}, "logging.googleapis.com/trace": "", "logging.googleapis.com/spanId": "", "logging.googleapis.com/trace_sampled": false, "logging.googleapis.com/sourceLocation": {"line": 224, "file": "/opt/pysetup/.venv/lib/python3.9/site-packages/django/utils/log.py", "function": "log_response"}, "httpRequest": {} }
{"message": "500 GET /accounts/google/login/ (10.68.13.6) 87.64ms","severity": "ERROR", "logging.googleapis.com/labels": {"python_logger": "hurricane.server.access"}, "logging.googleapis.com/trace": "", "logging.googleapis.com/spanId": "", "logging.googleapis.com/trace_sampled": false, "logging.googleapis.com/sourceLocation": {"line": 80, "file": "/opt/pysetup/.venv/lib/python3.9/site-packages/hurricane/server/__init__.py", "function": "log_request"}, "httpRequest": {} }